<?xml version="1.0"?>
<robot xmlns:xacro="http://www.ros.org/wiki/xacro">

    <xacro:include filename="inertial_macros.xacro"/>

    <material name="white">
        <color rgba ="1 1 1 1" />
    </material>

    <material name="black">
        <color rgba="0 0 0 1"/>
    </material>

    <!-- BASE -->
    <link name="base_link">
        
    </link>


    <!-- BASE_FOOTPRINT -->

    <joint name="base_footprint_joint" type="fixed">
        <parent link="base_link"/>
        <child link="base_footprint"/>
        <origin xyz="0.0 0.0 0.0" rpy="0.0 0.0 0.0"/>
    </joint>

    <link name="base_footprint">
    
    </link>
    
    <!-- CHASSIS -->
    <joint name="chassis_joint" type="fixed">
        <parent link="base_link"/>
        <child link="chassis"/>
        <origin xyz="-0.1 0.0 0.0"/>
    </joint>

    <link name="chassis">
        <visual>
            <origin xyz="0.15 0 0.075"/>
            <geometry>
                <box size="0.3 0.3 0.15"/>
            </geometry>
            <material name="white"/>
        </visual>

        <collision>
        <origin xyz="0.15 0 0.075"/>
            <geometry>
                <box size="0.3 0.3 0.15"/>
            </geometry>
        </collision>

        <xacro:inertial_box mass="0.5" x="0.3" y="0.3" z="0.15">
            <origin xyz="0.15 0.0 0.075"/>
        </xacro:inertial_box>
    </link>

    <gazebo reference="chassis">
        <material>Gazebo/White</material>
    </gazebo>

    <!-- LEFT WHEEL -->

    <joint name="left_wheel_joint" type="continuous">
        <parent link="base_link"/>
        <child link="left_wheel"/>
        <origin xyz="0.0 0.175 0.0" rpy="-${pi/2} 0.0 0.0"/>
        <axis xyz="0.0 0.0 1.0"/>
    </joint>

    <link name="left_wheel">
        <visual>
            <geometry>
                <cylinder radius="0.0762" length="0.0254"/>
            </geometry>    
            <material name="black"/>
        </visual>

        <collision>
            <geometry>
                <cylinder radius="0.0762" length="0.0254"/>
            </geometry>    
        </collision>

        <xacro:inertial_cylinder mass="0.1" length="0.0254" radius="0.0762">
            <origin xyz="0.0 0.0 0.0" rpy="0.0 0.0 0.0"/>
        </xacro:inertial_cylinder>
    </link>

    <gazebo reference="left_wheel">
        <material>Gazebo/Black</material>
    </gazebo>

    <!-- RIGHT WHEEL -->

    <joint name="right_wheel_joint" type="continuous">
        <parent link="base_link"/>
        <child link="right_wheel"/>
        <origin xyz="0.0 -0.175 0.0" rpy="${pi/2} 0.0 0.0"/>
        <axis xyz="0.0 0.0 1.0"/>
    </joint>

    <link name="right_wheel">
        <visual>
            <geometry>
                <cylinder radius="0.0762" length="0.0254"/>
            </geometry>    
            <material name="black"/>
        </visual>

        <collision>
            <geometry>
                <cylinder radius="0.0762" length="0.0254"/>
            </geometry>    
        </collision>

        <xacro:inertial_cylinder mass="0.1" length="0.0254" radius="0.0762">
            <origin xyz="0.0 0.0 0.0" rpy="0.0 0.0 0.0"/>
        </xacro:inertial_cylinder>
    </link>

    <gazebo reference="right_wheel">
        <material>Gazebo/Black</material>
    </gazebo>

    <!-- CASTER WHEEL-->

    <joint name="caster_wheel_join" type="fixed">
        <parent link="chassis"/>
        <child link="caster_wheel"/>
        <origin xyz="0.25 0.0 -0.04" rpy="-${pi/2} 0 0"/>
        <axis xyz="1.0 0 0"/>
    </joint>

    <link name="caster_wheel">
        <visual>
            <geometry>
                <cylinder radius="0.04" length="0.0254"/>
            </geometry>
            <material name="black"/>                
        </visual>

        <collision>
            <geometry>
                <sphere radius="0.04"/>
            </geometry>
        </collision>

        <xacro:inertial_sphere mass="0.1" radius="0.04">
            <origin xyz="0.0 0.0 0.0" rpy="0.0 0.0 0.0"/>
        </xacro:inertial_sphere>
    </link>

    <gazebo reference="caster_wheel">
        <material>Gazebo/Black</material>
        <mu1 value="0.001"/>
        <mu2 value="0.001"/>
    </gazebo>
</robot>
